2020-04-13 10:11:05,564 ERROR tfe_keeper._start_server:243 _start_server error , exception msg:Could not start gRPC server
Traceback (most recent call last):
  File "/Users/qizhi.zqz/projects/TFE_zqz/tf-encrypted/tfe_keeper/tfe_keeper.py", line 239, in _start_server
  File "/Users/qizhi.zqz/projects/TFE_zqz/tf-encrypted/tf_encrypted/config.py", line 282, in server
    start=start)
  File "/Users/qizhi.zqz/projects/TFE/tf-encrypted/venv/lib/python3.6/site-packages/tensorflow/python/training/server_lib.py", line 147, in __init__
    self._server = c_api.TF_NewServer(self._server_def.SerializeToString())
tensorflow.python.framework.errors_impl.UnknownError: Could not start gRPC server
2020-04-13 10:17:56,054 ERROR tfe_keeper._start_server:245 _start_server error , exception msg:Could not start gRPC server
Traceback (most recent call last):
  File "/Users/qizhi.zqz/projects/TFE_zqz/tf-encrypted/tfe_keeper/tfe_keeper.py", line 241, in _start_server
    server = config.server(Player, start=True)
  File "/Users/qizhi.zqz/projects/TFE_zqz/tf-encrypted/tf_encrypted/config.py", line 282, in server
    start=start)
  File "/Users/qizhi.zqz/projects/TFE/tf-encrypted/venv/lib/python3.6/site-packages/tensorflow/python/training/server_lib.py", line 147, in __init__
    self._server = c_api.TF_NewServer(self._server_def.SerializeToString())
tensorflow.python.framework.errors_impl.UnknownError: Could not start gRPC server
2020-04-13 11:29:55,129 ERROR train_and_predict_lr.run:357 train_and_predict.run() error , exception msg:too many indices for array
Traceback (most recent call last):
  File "/Users/qizhi.zqz/projects/TFE_zqz/tf-encrypted/tfe_keeper/train_and_predict_lr.py", line 343, in run
    batch_num, idx, predict_progress_file, YOwner.device_name, record_num_ceil_mod_batch_size)
  File "/Users/qizhi.zqz/projects/TFE_zqz/tf-encrypted/tfe_keeper/common_private.py", line 176, in predict
    records=records[0:record_num_ceil_mod_batch_size,:]
IndexError: too many indices for array
